Workbook

Sheet Graph and Stats
H2: Expected Unique Sparkling Critters | I2: Safari Runs | K2: 37/37 Probability | L2: Required Runs
H3: 20 | I3: {=INDEX('Run Model'!A$2:A$20002,MATCH(TRUE,'Run Model'!B$2:B$20002>=H3,0))} -> 441 | K3: 0.5 | L3: {=INDEX('Run Model'!A2:A20002,MATCH(TRUE,'Run Model'!C2:C20002>=50%,0))} -> 3839
H4: 21 | I4: {=INDEX('Run Model'!A$2:A$20002,MATCH(TRUE,'Run Model'!B$2:B$20002>=H4,0))} -> 478 | K4: 0.75 | L4: {=INDEX('Run Model'!A3:A20003,MATCH(TRUE,'Run Model'!C3:C20003>=75%,0))} -> 5304
H5: 22 | I5: {=INDEX('Run Model'!A$2:A$20002,MATCH(TRUE,'Run Model'!B$2:B$20002>=H5,0))} -> 519 | K5: 0.9 | L5: {=INDEX('Run Model'!A4:A20004,MATCH(TRUE,'Run Model'!C4:C20004>=90%,0))} -> 7164
H6: 23 | I6: {=INDEX('Run Model'!A$2:A$20002,MATCH(TRUE,'Run Model'!B$2:B$20002>=H6,0))} -> 563 | K6: 0.95 | L6: {=INDEX('Run Model'!A5:A20005,MATCH(TRUE,'Run Model'!C5:C20005>=95%,0))} -> 8559
H7: 24 | I7: {=INDEX('Run Model'!A$2:A$20002,MATCH(TRUE,'Run Model'!B$2:B$20002>=H7,0))} -> 612 | K7: 0.99 | L7: {=INDEX('Run Model'!A6:A20006,MATCH(TRUE,'Run Model'!C6:C20006>=99%,0))} -> 11798
H8: 25 | I8: {=INDEX('Run Model'!A$2:A$20002,MATCH(TRUE,'Run Model'!B$2:B$20002>=H8,0))} -> 665 | K8: 0.999 | L8: {=INDEX('Run Model'!A7:A20007,MATCH(TRUE,'Run Model'!C7:C20007>=99.9%,0))} -> 16457
H9: 26 | I9: {=INDEX('Run Model'!A$2:A$20002,MATCH(TRUE,'Run Model'!B$2:B$20002>=H9,0))} -> 724
H10: 27 | I10: {=INDEX('Run Model'!A$2:A$20002,MATCH(TRUE,'Run Model'!B$2:B$20002>=H10,0))} -> 791
H11: 28 | I11: {=INDEX('Run Model'!A$2:A$20002,MATCH(TRUE,'Run Model'!B$2:B$20002>=H11,0))} -> 866
H12: 29 | I12: {=INDEX('Run Model'!A$2:A$20002,MATCH(TRUE,'Run Model'!B$2:B$20002>=H12,0))} -> 953
H13: 30 | I13: {=INDEX('Run Model'!A$2:A$20002,MATCH(TRUE,'Run Model'!B$2:B$20002>=H13,0))} -> 1056
H14: 31 | I14: {=INDEX('Run Model'!A$2:A$20002,MATCH(TRUE,'Run Model'!B$2:B$20002>=H14,0))} -> 1179
H15: 32 | I15: {=INDEX('Run Model'!A$2:A$20002,MATCH(TRUE,'Run Model'!B$2:B$20002>=H15,0))} -> 1333
H16: 33 | I16: {=INDEX('Run Model'!A$2:A$20002,MATCH(TRUE,'Run Model'!B$2:B$20002>=H16,0))} -> 1534
H17: 34 | I17: {=INDEX('Run Model'!A$2:A$20002,MATCH(TRUE,'Run Model'!B$2:B$20002>=H17,0))} -> 1816
H18: 35 | I18: {=INDEX('Run Model'!A$2:A$20002,MATCH(TRUE,'Run Model'!B$2:B$20002>=H18,0))} -> 2263
H19: 36 | I19: {=INDEX('Run Model'!A$2:A$20002,MATCH(TRUE,'Run Model'!B$2:B$20002>=H19,0))} -> 3175
H20: 37 | I20: {=SUM(1-'Run Model'!C$2:C$20002)} -> 4365.8315
H21: Standard Deviation | I21: {=SQRT( SUM((2*'Run Model'!A$2:A$20002+1)* (1-'Run Model'!C$2:C$20002)) - SUM(1-'Run Model'!C$2:C$20002)^2 )} -> 2152.0676

Sheet Run Model
A1: Runs | B1: Expected Uniques | C1: Chance of 37/37
A2: {=SEQUENCE(20001,1,0,1)} -> 0 | B2: {=SUM(1-'Sparkling Model'!D$2:D$38^A2)} -> 0 | C2: {=PRODUCT(1-'Sparkling Model'!D$2:D$38^A2)} -> 0
A3: 1 | B3: {=SUM(1-'Sparkling Model'!D$2:D$38^A3)} -> 0.070734816 | C3: {=PRODUCT(1-'Sparkling Model'!D$2:D$38^A3)} -> 0
A4: 2 | B4: {=SUM(1-'Sparkling Model'!D$2:D$38^A4)} -> 0.14130912 | C4: {=PRODUCT(1-'Sparkling Model'!D$2:D$38^A4)} -> 0
A5: 3 | B5: {=SUM(1-'Sparkling Model'!D$2:D$38^A5)} -> 0.21172331 | C5: {=PRODUCT(1-'Sparkling Model'!D$2:D$38^A5)} -> 0
A6: 4 | B6: {=SUM(1-'Sparkling Model'!D$2:D$38^A6)} -> 0.2819778 | C6: {=PRODUCT(1-'Sparkling Model'!D$2:D$38^A6)} -> 0
A7: 5 | B7: {=SUM(1-'Sparkling Model'!D$2:D$38^A7)} -> 0.352073 | C7: {=PRODUCT(1-'Sparkling Model'!D$2:D$38^A7)} -> 0
A8: 6 | B8: {=SUM(1-'Sparkling Model'!D$2:D$38^A8)} -> 0.42200929 | C8: {=PRODUCT(1-'Sparkling Model'!D$2:D$38^A8)} -> 0
A9: 7 | B9: {=SUM(1-'Sparkling Model'!D$2:D$38^A9)} -> 0.49178709 | C9: {=PRODUCT(1-'Sparkling Model'!D$2:D$38^A9)} -> 0
A10: 8 | B10: {=SUM(1-'Sparkling Model'!D$2:D$38^A10)} -> 0.5614068 | C10: {=PRODUCT(1-'Sparkling Model'!D$2:D$38^A10)} -> 0
A11: 9 | B11: {=SUM(1-'Sparkling Model'!D$2:D$38^A11)} -> 0.63086881 | C11: {=PRODUCT(1-'Sparkling Model'!D$2:D$38^A11)} -> 0
A12: 10 | B12: {=SUM(1-'Sparkling Model'!D$2:D$38^A12)} -> 0.70017352 | C12: {=PRODUCT(1-'Sparkling Model'!D$2:D$38^A12)} -> 0
A13: 11 | B13: {=SUM(1-'Sparkling Model'!D$2:D$38^A13)} -> 0.76932133 | C13: {=PRODUCT(1-'Sparkling Model'!D$2:D$38^A13)} -> 0
A14: 12 | B14: {=SUM(1-'Sparkling Model'!D$2:D$38^A14)} -> 0.83831263 | C14: {=PRODUCT(1-'Sparkling Model'!D$2:D$38^A14)} -> 0
... A20002: 20000 | B20002: {=SUM(1-'Sparkling Model'!D$2:D$38^A20002)} -> 36.999825 | C20002: {=PRODUCT(1-'Sparkling Model'!D$2:D$38^A20002)} -> 0.999825

Sheet Sparkling Model
A1: Critter | B1: Spawns/Run | C1: Sparkling Chance/Run | D1: No Sparkling Chance/Run
A2: Cavernfish | B2: ='Critters Per Run'!C3 -> 6 | C2: =1-(1-1/2048)^B2 -> 0.0029261135 | D2: =1-C2 -> 0.99707389
A3: Flitter | B3: ='Critters Per Run'!C4 -> 7 | C3: =1-(1-1/2048)^B3 -> 0.003412966 | D3: =1-C3 -> 0.99658703
A4: Shyworm | B4: ='Critters Per Run'!C5 -> 6 | C4: =1-(1-1/2048)^B4 -> 0.0029261135 | D4: =1-C4 -> 0.99707389
A5: Driftling | B5: ='Critters Per Run'!C6 -> 4 | C5: =1-(1-1/2048)^B5 -> 0.001951695 | D5: =1-C5 -> 0.9980483
A6: Chuckwalla | B6: ='Critters Per Run'!C7 -> 3 | C6: =1-(1-1/2048)^B6 -> 0.0014641286 | D6: =1-C6 -> 0.99853587
A7: Rockmite | B7: ='Critters Per Run'!C8 -> 4.125 | C7: =1-(1-1/2048)^B7 -> 0.002012624 | D7: =1-C7 -> 0.99798738
A8: Scrappy | B8: ='Critters Per Run'!C9 -> 2.5 | C8: =1-(1-1/2048)^B8 -> 0.0012202561 | D8: =1-C8 -> 0.99877974
A9: Snoozle | B9: ='Critters Per Run'!C10 -> 2.5 | C9: =1-(1-1/2048)^B9 -> 0.0012202561 | D9: =1-C9 -> 0.99877974
A10: Gemzie | B10: ='Critters Per Run'!C11 -> 3 | C10: =1-(1-1/2048)^B10 -> 0.0014641286 | D10: =1-C10 -> 0.99853587
A11: Foxtrot | B11: ='Critters Per Run'!C13 -> 7 | C11: =1-(1-1/2048)^B11 -> 0.003412966 | D11: =1-C11 -> 0.99658703
A12: Bluebird | B12: ='Critters Per Run'!C14 -> 6.1996712 | C12: =1-(1-1/2048)^B12 -> 0.003023343 | D12: =1-C12 -> 0.99697666
A13: Honeybug | B13: ='Critters Per Run'!C15 -> 4.5 | C13: =1-(1-1/2048)^B13 -> 0.0021953888 | D13: =1-C13 -> 0.99780461
A14: Treefrog | B14: ='Critters Per Run'!C16 -> 4.5 | C14: =1-(1-1/2048)^B14 -> 0.0021953888 | D14: =1-C14 -> 0.99780461
A15: Woodchucker | B15: ='Critters Per Run'!C17 -> 4.5 | C15: =1-(1-1/2048)^B15 -> 0.0021953888 | D15: =1-C15 -> 0.99780461
A16: Fluffling | B16: ='Critters Per Run'!C18 -> 2 | C16: =1-(1-1/2048)^B16 -> 0.00097632408 | D16: =1-C16 -> 0.99902368
A17: Hideonfloor | B17: ='Critters Per Run'!C19 -> 2 | C17: =1-(1-1/2048)^B17 -> 0.00097632408 | D17: =1-C17 -> 0.99902368
A18: Parakeet | B18: ='Critters Per Run'!C20 -> 3.1534152 | C18: =1-(1-1/2048)^B18 -> 0.0015389442 | D18: =1-C18 -> 0.99846106
A19: Macaw | B19: ='Critters Per Run'!C21 -> 1.2938271 | C19: =1-(1-1/2048)^B19 -> 0.00063170619 | D19: =1-C19 -> 0.99936829
A20: Areita | B20: ='Critters Per Run'!C23 -> 4.5 | C20: =1-(1-1/2048)^B20 -> 0.0021953888 | D20: =1-C20 -> 0.99780461
A21: Bloodbat | B21: ='Critters Per Run'!C24 -> 4.5 | C21: =1-(1-1/2048)^B21 -> 0.0021953888 | D21: =1-C21 -> 0.99780461
A22: Duplico | B22: ='Critters Per Run'!C25 -> 3 | C22: =1-(1-1/2048)^B22 -> 0.0014641286 | D22: =1-C22 -> 0.99853587
A23: Gazer | B23: ='Critters Per Run'!C26 -> 4 | C23: =1-(1-1/2048)^B23 -> 0.001951695 | D23: =1-C23 -> 0.9980483
A24: Litterbug | B24: ='Critters Per Run'!C27 -> 5 | C24: =1-(1-1/2048)^B24 -> 0.0024390232 | D24: =1-C24 -> 0.99756098
A25: Solsnatcher | B25: ='Critters Per Run'!C28 -> 6 | C25: =1-(1-1/2048)^B25 -> 0.0029261135 | D25: =1-C25 -> 0.99707389
A26: Gimmiegold | B26: ='Critters Per Run'!C29 -> 4.7222222 | C26: =1-(1-1/2048)^B26 -> 0.0023036781 | D26: =1-C26 -> 0.99769632
A27: Hideonwall | B27: ='Critters Per Run'!C30 -> 3 | C27: =1-(1-1/2048)^B27 -> 0.0014641286 | D27: =1-C27 -> 0.99853587
A28: Hideyho | B28: ='Critters Per Run'!C31 -> 1 | C28: =1-(1-1/2048)^B28 -> 0.00048828125 | D28: =1-C28 -> 0.99951172
A29: Doomspiral | B29: ='Critters Per Run'!C32 -> 1 | C29: =1-(1-1/2048)^B29 -> 0.00048828125 | D29: =1-C29 -> 0.99951172
A30: Strongarm | B30: ='Critters Per Run'!C34 -> 6 | C30: =1-(1-1/2048)^B30 -> 0.0029261135 | D30: =1-C30 -> 0.99707389
A31: Tepid | B31: ='Critters Per Run'!B35 -> 7 | C31: =1-(1-1/2048)^B31 -> 0.003412966 | D31: =1-C31 -> 0.99658703
A32: Polaris | B32: ='Critters Per Run'!B36 -> 3 | C32: =1-(1-1/2048)^B32 -> 0.0014641286 | D32: =1-C32 -> 0.99853587
A33: Shuddersquid | B33: ='Critters Per Run'!B37 -> 4.5 | C33: =1-(1-1/2048)^B33 -> 0.0021953888 | D33: =1-C33 -> 0.99780461
A34: Billygoat | B34: ='Critters Per Run'!B38 -> 3 | C34: =1-(1-1/2048)^B34 -> 0.0014641286 | D34: =1-C34 -> 0.99853587
A35: Mantis Shrimp | B35: ='Critters Per Run'!B39 -> 4.5 | C35: =1-(1-1/2048)^B35 -> 0.0021953888 | D35: =1-C35 -> 0.99780461
A36: Nozzlenose | B36: ='Critters Per Run'!B40 -> 3 | C36: =1-(1-1/2048)^B36 -> 0.0014641286 | D36: =1-C36 -> 0.99853587
A37: Troodon | B37: ='Critters Per Run'!B41 -> 3 | C37: =1-(1-1/2048)^B37 -> 0.0014641286 | D37: =1-C37 -> 0.99853587
A38: Wumpa | B38: ='Critters Per Run'!B42 -> 1 | C38: =1-(1-1/2048)^B38 -> 0.00048828125 | D38: =1-C38 -> 0.99951172

Sheet Critters Per Run
A1: Critter | B1: Avg Critters per Run (Full Party) | C1: Avg Critters per Run (Lazy Party) | D1: Ranges (Full Party) | F1: *Critter Safari came out on August 4th
A2: CAVERN | F2: August 11 Patch
A3: Cavernfish | B3: 6 | C3: 6 | D3: 46120 | F3: Adjusted the spawn amounts of some Critter Safari mobs:
A4: Flitter | B4: 7 | C4: 7 | D4: 46181 | F4: Areita: 2-4 -> 3-6
A5: Shyworm | B5: 6 | C5: 6 | D5: 46120 | F5: Billygoat: 1 -> 2-4
A6: Driftling | B6: 4.5 | C6: 4 | D6: 46087 | F6: Bloodbat: 2-4 -> 3-6
A7: Chuckwalla | B7: 3 | C7: 3 | D7: 46057 | F7: Tepid: 8-12 -> 6-8
A8: Rockmite | B8: =CalculationsNotesTests!F14 -> 4.125 | C8: =CalculationsNotesTests!F14 -> 4.125 | D8: 0-12** | F8: Gazer: 2 -> 4
A9: Scrappy | B9: 3 | C9: 2.5 | D9: 3 | F9: Flitter: 3-6 -> 6-8
A10: Snoozle | B10: 2.5 | C10: 2.5 | D10: 0-5 | F10: Foxtrot: 3-6 -> 6-8
A11: Gemzie | B11: 3 | C11: 3 | D11: 3 | F11: Adjusted locations and amounts of some Floor Drops in the Critter Safari:
A12: FOREST | F12: Yogi Berry: 3-6 across all biomes -> 3 guaranteed in Forest Biome
A13: Foxtrot | B13: 7 | C13: 7 | D13: 46181 | F13: Wriggleworm: 3-6 across all biomes -> 3 guaranteed in Forest Biome
A14: Bluebird | B14: =CalculationsNotesTests!$L45*CalculationsNotesTests!$J21 -> 7.2329497 | C14: =10*CalculationsNotesTests!$J21 -> 6.1996712 | D14: 0-12** | F14: Bag of Seeds: 3-6 across all biomes -> 3 guaranteed in Forest Biome
A15: Honeybug | B15: 4.5 | C15: 4.5 | D15: 46087
A16: Treefrog | B16: 4.5 | C16: 4.5 | D16: 46087 | F16: ** - Calculated in Calculations/Notes/Tests Tab
A17: Woodchucker | B17: 4.5 | C17: 4.5 | D17: 46087
A18: Fluffling | B18: 2 | C18: 2 | D18: 46025
A19: Hideonfloor | B19: 2 | C19: 2 | D19: 46025
A20: Parakeet | B20: =CalculationsNotesTests!$L45*CalculationsNotesTests!$L21 -> 3.6789845 | C20: =10*CalculationsNotesTests!$L21 -> 3.1534152 | D20: 0-12**
A21: Macaw | B21: =(CalculationsNotesTests!$L45*CalculationsNotesTests!$N21)*2 -> 1.509465 | C21: =(10*CalculationsNotesTests!$N21)*2 -> 1.2938271 | D21: 0-16**
A22: HAUNTED
A23: Areita | B23: 4.5 | C23: 4.5 | D23: 46087
A24: Bloodbat | B24: 4.5 | C24: 4.5 | D24: 46087
A25: Duplico | B25: 3 | C25: 3 | D25: 46057
A26: Gazer | B26: 4 | C26: 4 | D26: 4
A27: Litterbug | B27: 6 | C27: 5 | D27: 46120
A28: Solsnatcher | B28: 6 | C28: 6 | D28: 46120
A29: Gimmiegold | B29: =4.5+(8*CalculationsNotesTests!$L48) -> 5.3888889 | C29: =4.5+(2*CalculationsNotesTests!$L48) -> 4.7222222 | D29: 3-10**
A30: Hideonwall | B30: 3 | C30: 3 | D30: 46057
A31: Hideyho | B31: 1 | C31: 1 | D31: 1
A32: Doomspiral | B32: 1 | C32: 1 | D32: 1
A33: ICY
A34: Strongarm | B34: 6 | C34: 6 | D34: 46120
A35: Tepid | B35: 7 | C35: 7 | D35: 46181
A36: Polaris | B36: 3 | C36: 3 | D36: 46057
A37: Shuddersquid | B37: 4.5 | C37: 4.5 | D37: 46087
A38: Billygoat | B38: 3 | C38: 3 | D38: 46057
A39: Mantis Shrimp | B39: 4.5 | C39: 4.5 | D39: 46087
A40: Nozzlenose | B40: 3 | C40: 3 | D40: 46057
...

Sheet Runs Per Sparkling
A1: AVG TOTAL CRITTERS PER RUN | D1: RUNS PER SPARKLING CRITTER
A2: ='Critters Per Run'!C44 -> 144.99414
D4: =2048/A2 -> 14.124709
A5: SPARKLE CHANCE
A6: 54058

Sheet CalculationsNotesTests
A1: Rockmite Trials (W/ 10 Tracking Perk) | E1: AVG Mounds/Run | F1: =AVERAGE(B3:B1000) -> 14.573913
A2: Run | B2: # of Mounds | C2: # of Rockmites | E2: AVG Rockmites/Run | F2: =AVERAGE(C3:C1000) -> 4.1391304 | H2: Link to photo
A3: {=SEQUENCE(115,1,1,1)} -> 1 | B3: 12 | C3: 4
A4: 2 | B4: 17 | C4: 3 | E4: Minimum Mounds/Run | F4: =MIN(B3:B1000) -> 10
A5: 3 | B5: 13 | C5: 4 | E5: Maximum Mounds/Run | F5: =MAX(B3:B1000) -> 20
A6: 4 | B6: 15 | C6: 5
A7: 5 | B7: 10 | C7: 4 | E7: Minimum Rockmites/Run | F7: =MIN(C3:C1000) -> 0
A8: 6 | B8: 18 | C8: 9 | E8: Maximum Rockmites/Run | F8: =MAX(C3:C1000) -> 9
A9: 7 | B9: 15 | C9: 3
A10: 8 | B10: 11 | C10: 1 | E10: Experimental Rockmite Chance/Mound | F10: =SUM(C3:C1000)/SUM(B3:B1000) -> 0.28400955
A11: 9 | B11: 12 | C11: 5 | E11: Theoretical Rockmite Chance/Mound | F11: 0.275
A12: 10 | B12: 12 | C12: 0
A13: 11 | B13: 17 | C13: 6 | E13: Assumed Mounds/Run | F13: 15
A14: 12 | B14: 17 | C14: 4 | E14: Assumed Rockmites/Run | F14: =F13*F11 -> 4.125
A15: 13 | B15: 12 | C15: 4
A16: 14 | B16: 20 | C16: 6 | I16: Blubird Overall Chance | K16: Parakeet Overall Chance | M16: Macaw Overall Chance
A17: 15 | B17: 19 | C17: 3 | I17: Weight | J17: Chance | K17: Weight | L17: Chance | M17: Weight w/ Tracking | N17: Chance | P17: Weight Total for each Bird Food
A18: 16 | B18: 11 | C18: 5 | E18: Total Runs Tracked | H18: Yogi Berry | I18: 18 | J18: =I18/P18 -> 0.71400238 | K18: 6 | L18: =K18/P18 -> 0.23800079 | M18: =1.1^2 -> 1.21 | N18: =M18/P18 -> 0.047996827 | P18: =SUM(I18,K18,M18) -> 25.21
A19: 17 | B19: 10 | C19: 3 | H19: Wriggleworm | I19: 12 | J19: =I19/P19 -> 0.54029716 | K19: 9 | L19: =K19/P19 -> 0.40522287 | M19: =1.1^2 -> 1.21 | N19: =M19/P19 -> 0.054479964 | P19: =SUM(I19,K19,M19) -> 22.21
A20: 18 | B20: 19 | C20: 4 | E20: =MAX(A3:A1000) -> 115 | H20: Bag of Seeds | I20: 12 | J20: =I20/P20 -> 0.60560182 | K20: 6 | L20: =K20/P20 -> 0.30280091 | M20: =1.5*(1.1^2) -> 1.815 | N20: =M20/P20 -> 0.091597275 | P20: =SUM(I20,K20,M20) -> 19.815
A21: 19 | B21: 11 | C21: 3 | H21: Avg Chance | J21: =AVERAGE(J18:J20) -> 0.61996712 | L21: =AVERAGE(L18:L20) -> 0.31534152 | M21: =I2 | N21: =AVERAGE(N18:N20) -> 0.064691355
A22: 20 | B22: 17 | C22: 2 | M22: *It is believed that the tracking on Macaws counts twice since there are 2 macaws that spawn
A23: 21 | B23: 19 | C23: 3
A24: 22 | B24: 11 | C24: 5 | H24: Link to photo
A25: 23 | B25: 19 | C25: 7
A26: 24 | B26: 19 | C26: 7
A27: 25 | B27: 13 | C27: 3
A28: 26 | B28: 15 | C28: 3
A29: 27 | B29: 10 | C29: 2
A30: 28 | B30: 13 | C30: 5
A31: 29 | B31: 13 | C31: 3
A32: 30 | B32: 13 | C32: 5
A33: 31 | B33: 18 | C33: 9
A34: 32 | B34: 18 | C34: 5
A35: 33 | B35: 10 | C35: 3
A36: 34 | B36: 11 | C36: 3
... A38: 36 | B38: 18 | C38: 2
A39: 37 | B39: 15 | C39: 2 | I39: List of random items to get at start of run | L39: Chance to get Bird food for each random item
A40: 38 | B40: 18 | C40: 4 | I40: Purple Gem | J40: 1 | L40: =SUM(J43:J45)/SUM(J40:J48) -> 0.33333333
A41: 39 | B41: 18 | C41: 5 | I41: Lime Gem | J41: 1
...
